<?xml version="1.0"?>
<robot name="myfirst">
  <link name="base_link">
    <visual>
      <origin xyz="0 0 0" rpy="0 0 0" />
      <geometry>
        <cylinder length="1" radius="0.1"/>
      </geometry>
    </visual>
  </link>
<joint name="joint1" type="continuous">    
    <parent link="base_link"/>
    <child link="arm_link"/>
    <origin xyz="0 0 0" rpy="0 0 1.57"/>
    <axis xyz="0 1 0" /> <!-- This is the axis to rotate -->
</joint>
<link name="arm_link">
    <visual>
     <origin xyz="1.5 0 0.5" rpy="1.57 0 0" />
      <geometry>
        <cylinder length="3" radius="0.05"/>
      </geometry>
    </visual>
  </link>
</robot>
